

  ========= 测试开始 : 20230207_221007 =========



>>> cases\API\空白环境\

[ suite setup ] cases\API\空白环境\
suite_setup

-- 第 1 步 -- 清空所有学生/老师/班级 



>>> cases\API\空白环境\存在班级\

[ suite setup ] cases\API\空白环境\存在班级\

-- 第 1 步 -- 添加班级 

old初始班级id:20430


>>> cases\API\空白环境\存在班级\excl_class.py

* 添加班级3  -  2023-02-07 22:10:11

  [ case execution steps ]

-- 第 1 步 -- 添加相同名称的班级 

接口返回{'reason': 'Traceback (most recent call last):\n  File "/home/yjyx/yijiao_src/yijiao_main/services/datamodel/schoolclass/models.py", line 542, in addClass\n    school_class = self._addClass(name,schoolid,gradeid,studentlimit)\n  File "/home/yjyx/yijiao_src/yijiao_main/services/datamodel/schoolclass/models.py", line 531, in _addClass\n    school_class.save()\n  File "/usr/local/lib/python2.7/site-packages/django/db/models/base.py", line 710, in save\n    force_update=force_update, update_fields=update_fields)\n  File "/usr/local/lib/python2.7/site-packages/django/db/models/base.py", line 738, in save_base\n    updated = self._save_table(raw, cls, force_insert, force_update, using, update_fields)\n  File "/usr/local/lib/python2.7/site-packages/django/db/models/base.py", line 822, in _save_table\n    result = self._do_insert(cls._base_manager, using, fields, update_pk, raw)\n  File "/usr/local/lib/python2.7/site-packages/django/db/models/base.py", line 861, in _do_insert\n    using=using, raw=raw)\n  File "/usr/local/lib/python2.7/site-packages/django/db/models/manager.py", line 127, in manager_method\n    return getattr(self.get_queryset(), name)(*args, **kwargs)\n  File "/usr/local/lib/python2.7/site-packages/django/db/models/query.py", line 920, in _insert\n    return query.get_compiler(using=using).execute_sql(return_id)\n  File "/usr/local/lib/python2.7/site-packages/django/db/models/sql/compiler.py", line 974, in execute_sql\n    cursor.execute(sql, params)\n  File "/usr/local/lib/python2.7/site-packages/django/db/backends/utils.py", line 64, in execute\n    return self.cursor.execute(sql, params)\n  File "/usr/local/lib/python2.7/site-packages/django/db/utils.py", line 97, in __exit__\n    six.reraise(dj_exc_type, dj_exc_value, traceback)\n  File "/usr/local/lib/python2.7/site-packages/django/db/backends/utils.py", line 64, in execute\n    return self.cursor.execute(sql, params)\n  File "/usr/local/lib/python2.7/site-packages/django/db/backends/mysql/base.py", line 124, in execute\n    return self.cursor.execute(query, args)\n  File "/usr/local/lib/python2.7/site-packages/MySQLdb/cursors.py", line 205, in execute\n    self.errorhandler(self, exc, value)\n  File "/usr/local/lib/python2.7/site-packages/MySQLdb/connections.py", line 36, in defaulterrorhandler\n    raise errorclass, errorvalue\nIntegrityError: (1062, "Duplicate entry \'\\xe5\\x88\\x9d\\xe5\\xa7\\x8b\\xe7\\x8f\\xad\\xe7\\xba\\xa7-407-1\' for key \'name\'")\n', 'retcode': 1}
接口返回Traceback (most recent call last):
  File "/home/yjyx/yijiao_src/yijiao_main/services/datamodel/schoolclass/models.py", line 542, in addClass
    school_class = self._addClass(name,schoolid,gradeid,studentlimit)
  File "/home/yjyx/yijiao_src/yijiao_main/services/datamodel/schoolclass/models.py", line 531, in _addClass
    school_class.save()
  File "/usr/local/lib/python2.7/site-packages/django/db/models/base.py", line 710, in save
    force_update=force_update, update_fields=update_fields)
  File "/usr/local/lib/python2.7/site-packages/django/db/models/base.py", line 738, in save_base
    updated = self._save_table(raw, cls, force_insert, force_update, using, update_fields)
  File "/usr/local/lib/python2.7/site-packages/django/db/models/base.py", line 822, in _save_table
    result = self._do_insert(cls._base_manager, using, fields, update_pk, raw)
  File "/usr/local/lib/python2.7/site-packages/django/db/models/base.py", line 861, in _do_insert
    using=using, raw=raw)
  File "/usr/local/lib/python2.7/site-packages/django/db/models/manager.py", line 127, in manager_method
    return getattr(self.get_queryset(), name)(*args, **kwargs)
  File "/usr/local/lib/python2.7/site-packages/django/db/models/query.py", line 920, in _insert
    return query.get_compiler(using=using).execute_sql(return_id)
  File "/usr/local/lib/python2.7/site-packages/django/db/models/sql/compiler.py", line 974, in execute_sql
    cursor.execute(sql, params)
  File "/usr/local/lib/python2.7/site-packages/django/db/backends/utils.py", line 64, in execute
    return self.cursor.execute(sql, params)
  File "/usr/local/lib/python2.7/site-packages/django/db/utils.py", line 97, in __exit__
    six.reraise(dj_exc_type, dj_exc_value, traceback)
  File "/usr/local/lib/python2.7/site-packages/django/db/backends/utils.py", line 64, in execute
    return self.cursor.execute(sql, params)
  File "/usr/local/lib/python2.7/site-packages/django/db/backends/mysql/base.py", line 124, in execute
    return self.cursor.execute(query, args)
  File "/usr/local/lib/python2.7/site-packages/MySQLdb/cursors.py", line 205, in execute
    self.errorhandler(self, exc, value)
  File "/usr/local/lib/python2.7/site-packages/MySQLdb/connections.py", line 36, in defaulterrorhandler
    raise errorclass, errorvalue
IntegrityError: (1062, "Duplicate entry '\xe5\x88\x9d\xe5\xa7\x8b\xe7\x8f\xad\xe7\xba\xa7-407-1' for key 'name'")


** 检查点 **  检查返回结果 ---->  !! 不通过!!

  FAIL    
Traceback:
  File "cases\API\空白环境\存在班级\excl_class.py", line 35, in teststeps
    CHECK_POINT('检查返回结果', reason == 'duplicated class name')
  File "D:\Python39\lib\site-packages\hytest\common.py", line 58, in CHECK_POINT
    raise AssertionError()
AssertionError



  ========= 测试结束 : 20230207_221011 =========


  耗时    : 3.501 秒


  预备执行用例数量 : 1

  实际执行用例数量 : 1

  通过 : 0

  失败 : 1

  异常 : 0

  套件初始化失败 : 0

  套件清除  失败 : 0

  用例初始化失败 : 0

  用例清除  失败 : 0
